Workbook

Sheet 📊 Dashboard
A1: WEHOME / WEOFFICE — TABLEAU DE BORD
A2: ="Total : "&COUNTA('📋 Leads'!G2:G611)&" | 🔥 Immédiats : "&COUNTIF('📋 Leads'!C2:C611,"🔥 Immédiatement")&" | 🔄 En cours : "&COUNTIF('📋 Leads'!B2:B611,"🔄 En cours")&" | ✅ Gagnés : "&COUNTIF('📋 Leads'!B2:B611,"✅ Gagné") -> Total : 561 | 🔥 Immédiats : 250 | 🔄 En cours : 48 | ✅ Gagnés : 0
A4: =COUNTA('📋 Leads'!G2:G611) -> 561 | B4: =COUNTIF('📋 Leads'!C2:C611,"🔥 Immédiatement") -> 250 | C4: =COUNTIF('📋 Leads'!C2:C611,"📅 Dans 1 mois") -> 130 | D4: =COUNTIF('📋 Leads'!C2:C611,"📅 2-3 mois") -> 122 | E4: =COUNTIF('📋 Leads'!B2:B611,"🔄 En cours") -> 48 | F4: =COUNTIF('📋 Leads'!B2:B611,"✅ Gagné") -> 0 | G4: =COUNTIF('📋 Leads'!M2:M611,"✅") -> 146 | H4: =COUNTA('🏠 Biens'!B2:B200) -> 47 | I4: =COUNTIF('📋 Leads'!D2:D611,"🔴 Haute") -> 234
A5: Leads totaux | B5: 🔥 Immédiats | C5: 📅 Dans 1 mois | D5: 📅 2-3 mois | E5: 🔄 En cours | F5: ✅ Gagnés | G5: 📝 Avec notes | H5: 🏠 Biens actifs | I5: 🔴 Chauds
A7: ⏰ URGENCE × CATÉGORIE
A8: Urgence | B8: Total | C8: Achat | D8: Location | E8: Vente | F8: Investissement | G8: Louer son bien | H8: 🔄 En cours | I8: 📝 Notes
A9: 🔥 Immédiatement | B9: =COUNTIF('📋 Leads'!C2:C611,"🔥 Immédiatement") -> 250 | C9: =COUNTIFS('📋 Leads'!C2:C611,"🔥 Immédiatement",'📋 Leads'!E2:E611,"Achat") -> 81 | D9: =COUNTIFS('📋 Leads'!C2:C611,"🔥 Immédiatement",'📋 Leads'!E2:E611,"Location") -> 151 | E9: =COUNTIFS('📋 Leads'!C2:C611,"🔥 Immédiatement",'📋 Leads'!E2:E611,"Vente") -> 5 | F9: =COUNTIFS('📋 Leads'!C2:C611,"🔥 Immédiatement",'📋 Leads'!E2:E611,"Investissement") -> 2 | G9: =COUNTIFS('📋 Leads'!C2:C611,"🔥 Immédiatement",'📋 Leads'!E2:E611,"Louer son bien") -> 11 | H9: =COUNTIFS('📋 Leads'!C2:C611,"🔥 Immédiatement",'📋 Leads'!B2:B611,"🔄 En cours") -> 32 | I9: =COUNTIFS('📋 Leads'!C2:C611,"🔥 Immédiatement",'📋 Leads'!M2:M611,"✅") -> 66
A10: 📅 Dans 1 mois | B10: =COUNTIF('📋 Leads'!C2:C611,"📅 Dans 1 mois") -> 130 | C10: =COUNTIFS('📋 Leads'!C2:C611,"📅 Dans 1 mois",'📋 Leads'!E2:E611,"Achat") -> 71 | D10: =COUNTIFS('📋 Leads'!C2:C611,"📅 Dans 1 mois",'📋 Leads'!E2:E611,"Location") -> 54 | E10: =COUNTIFS('📋 Leads'!C2:C611,"📅 Dans 1 mois",'📋 Leads'!E2:E611,"Vente") -> 1 | F10: =COUNTIFS('📋 Leads'!C2:C611,"📅 Dans 1 mois",'📋 Leads'!E2:E611,"Investissement") -> 2 | G10: =COUNTIFS('📋 Leads'!C2:C611,"📅 Dans 1 mois",'📋 Leads'!E2:E611,"Louer son bien") -> 1 | H10: =COUNTIFS('📋 Leads'!C2:C611,"📅 Dans 1 mois",'📋 Leads'!B2:B611,"🔄 En cours") -> 9 | I10: =COUNTIFS('📋 Leads'!C2:C611,"📅 Dans 1 mois",'📋 Leads'!M2:M611,"✅") -> 49
A11: 📅 2-3 mois | B11: =COUNTIF('📋 Leads'!C2:C611,"📅 2-3 mois") -> 122 | C11: =COUNTIFS('📋 Leads'!C2:C611,"📅 2-3 mois",'📋 Leads'!E2:E611,"Achat") -> 45 | D11: =COUNTIFS('📋 Leads'!C2:C611,"📅 2-3 mois",'📋 Leads'!E2:E611,"Location") -> 75 | E11: =COUNTIFS('📋 Leads'!C2:C611,"📅 2-3 mois",'📋 Leads'!E2:E611,"Vente") -> 0 | F11: =COUNTIFS('📋 Leads'!C2:C611,"📅 2-3 mois",'📋 Leads'!E2:E611,"Investissement") -> 0 | G11: =COUNTIFS('📋 Leads'!C2:C611,"📅 2-3 mois",'📋 Leads'!E2:E611,"Louer son bien") -> 2 | H11: =COUNTIFS('📋 Leads'!C2:C611,"📅 2-3 mois",'📋 Leads'!B2:B611,"🔄 En cours") -> 4 | I11: =COUNTIFS('📋 Leads'!C2:C611,"📅 2-3 mois",'📋 Leads'!M2:M611,"✅") -> 17
A12: 📅 3-6 mois | B12: =COUNTIF('📋 Leads'!C2:C611,"📅 3-6 mois") -> 50 | C12: =COUNTIFS('📋 Leads'!C2:C611,"📅 3-6 mois",'📋 Leads'!E2:E611,"Achat") -> 50 | D12: =COUNTIFS('📋 Leads'!C2:C611,"📅 3-6 mois",'📋 Leads'!E2:E611,"Location") -> 0 | E12: =COUNTIFS('📋 Leads'!C2:C611,"📅 3-6 mois",'📋 Leads'!E2:E611,"Vente") -> 0 | F12: =COUNTIFS('📋 Leads'!C2:C611,"📅 3-6 mois",'📋 Leads'!E2:E611,"Investissement") -> 0 | G12: =COUNTIFS('📋 Leads'!C2:C611,"📅 3-6 mois",'📋 Leads'!E2:E611,"Louer son bien") -> 0 | H12: =COUNTIFS('📋 Leads'!C2:C611,"📅 3-6 mois",'📋 Leads'!B2:B611,"🔄 En cours") -> 0 | I12: =COUNTIFS('📋 Leads'!C2:C611,"📅 3-6 mois",'📋 Leads'!M2:M611,"✅") -> 7
A13: 🕐 +6 mois | B13: =COUNTIF('📋 Leads'!C2:C611,"🕐 +6 mois") -> 2 | C13: =COUNTIFS('📋 Leads'!C2:C611,"🕐 +6 mois",'📋 Leads'!E2:E611,"Achat") -> 1 | D13: =COUNTIFS('📋 Leads'!C2:C611,"🕐 +6 mois",'📋 Leads'!E2:E611,"Location") -> 1 | E13: =COUNTIFS('📋 Leads'!C2:C611,"🕐 +6 mois",'📋 Leads'!E2:E611,"Vente") -> 0 | F13: =COUNTIFS('📋 Leads'!C2:C611,"🕐 +6 mois",'📋 Leads'!E2:E611,"Investissement") -> 0 | G13: =COUNTIFS('📋 Leads'!C2:C611,"🕐 +6 mois",'📋 Leads'!E2:E611,"Louer son bien") -> 0 | H13: =COUNTIFS('📋 Leads'!C2:C611,"🕐 +6 mois",'📋 Leads'!B2:B611,"🔄 En cours") -> 0 | I13: =COUNTIFS('📋 Leads'!C2:C611,"🕐 +6 mois",'📋 Leads'!M2:M611,"✅") -> 1
A15: 👥 ÉQUIPE
A16: Agent | B16: Leads assignés | C16: 🔄 En cours | D16: ✅ Gagnés | E16: 🔥 Immédiats | F16: 📝 Notes
A17: 👑 Karim Zniber | B17: =COUNTIF('📋 Leads'!J2:J611,"*Karim*") -> 44 | C17: =COUNTIFS('📋 Leads'!J2:J611,"*Karim*",'📋 Leads'!B2:B611,"🔄 En cours") -> 21 | D17: =COUNTIFS('📋 Leads'!J2:J611,"*Karim*",'📋 Leads'!B2:B611,"✅ Gagné") -> 0 | E17: =COUNTIFS('📋 Leads'!J2:J611,"*Karim*",'📋 Leads'!C2:C611,"🔥 Immédiatement") -> 27 | F17: =COUNTIFS('📋 Leads'!J2:J611,"*Karim*",'📋 Leads'!M2:M611,"✅") -> 43
A18: 🟣 Oumaima | B18: =COUNTIF('📋 Leads'!J2:J611,"*Oumaima*") -> 4 | C18: =COUNTIFS('📋 Leads'!J2:J611,"*Oumaima*",'📋 Leads'!B2:B611,"🔄 En cours") -> 4 | D18: =COUNTIFS('📋 Leads'!J2:J611,"*Oumaima*",'📋 Leads'!B2:B611,"✅ Gagné") -> 0 | E18: =COUNTIFS('📋 Leads'!J2:J611,"*Oumaima*",'📋 Leads'!C2:C611,"🔥 Immédiatement") -> 1 | F18: =COUNTIFS('📋 Leads'!J2:J611,"*Oumaima*",'📋 Leads'!M2:M611,"✅") -> 4 | G18: Je ne suis pas agent :) | I18: wakha a khti
A19: 🔵 Basma | B19: =COUNTIF('📋 Leads'!J2:J611,"*Basma*") -> 107 | C19: =COUNTIFS('📋 Leads'!J2:J611,"*Basma*",'📋 Leads'!B2:B611,"🔄 En cours") -> 1 | D19: =COUNTIFS('📋 Leads'!J2:J611,"*Basma*",'📋 Leads'!B2:B611,"✅ Gagné") -> 0 | E19: =COUNTIFS('📋 Leads'!J2:J611,"*Basma*",'📋 Leads'!C2:C611,"🔥 Immédiatement") -> 49 | F19: =COUNTIFS('📋 Leads'!J2:J611,"*Basma*",'📋 Leads'!M2:M611,"✅") -> 14

Sheet 📋 Leads
A1: # | B1: Statut | C1: Urgence | D1: Priorité | E1: Categorie | F1: Budget | G1: Téléphone | H1: Nom | I1: Prénom | J1: Agent | K1: Dernière relance | L1: Prochain RDV | M1: ✅ | N1: Notes / Journal | O1: Financement | P1: Ville | Q1: Type / Bien visé | R1: Email | S1: ID Bien
A2: 1 | B2: 🔄 En cours | C2: 🔥 Immédiatement | D2: 🔴 Haute | E2: Achat | F2: -1M MAD | G2: 212661155868 | H2: بن عبد الواحد عبد الكريم | J2: Karim Zniber | M2: ✅ | N2: Studio pour sa fille Les hopitaux / 2 mars / Oasis / Palmiers MAD1M max, acheter cash | Couple | O2: Cash | P2: Casablanca | Q2: studio ferme brettone | R2: Konouz.cmda@gmail.com
A3: 2 | B3: 🔄 En cours | C3: 🔥 Immédiatement | D3: 🔴 Haute | E3: Achat | F3: -1M MAD | G3: 212673683526 | H3: عبدالله Mohamedboutazi | J3: Karim Zniber | M3: ✅ | N3: Contactez finalement, 900,000MAD budget max, studio investissement, cash, oasis, ferme bretonne,CFC, achat immediat si on lui trouve le bien. Il a trouve a 850,000MAD mais pas ensoleille | Famille | O3: Cash | P3: Casablanca | Q3: studio CFC | R3: bouhlalabdellah65@gmail.com
A4: 3 | B4: 🔄 En cours | C4: 🔥 Immédiatement | D4: 🔴 Haute | E4: Achat | F4: 2M-4M MAD | G4: 212644000574 | H4: Zekri | I4: Nadia | M4: ✅ | N4: Deja contacter, max 3,3mdh sans travaux/ repond plus après proposition des bien | R4: nadia.zekri1981@gmail.com | S4: —
A5: 4 | B5: 🔄 En cours | C5: 🔥 Immédiatement | D5: 🔴 Haute | E5: Achat | F5: -1M MAD | G5: 212684320216 | H5: Koutoun | I5: Ilyass | J5: Karim Zniber | M5: ✅ | N5: recherche un bien avec un budget 1m 2 max travazil a ain sba. prefere 1er ou 2 eme etage ensoleillé neuf | P5: Casa | R5: oued-bil@live.fr | S5: —
A6: 5 | B6: 🔄 En cours | C6: 🔥 Immédiatement | D6: 🔴 Haute | E6: Achat | F6: 2M-4M MAD | G6: 212661331168 | H6: Cherkaoui | I6: Mehdi | J6: Karim Zniber | M6: ✅ | N6: Cherche apprt 4ch racine/gauthier budget 3,5 | P6: Casa | R6: cherkaoui.m81@gmail.com | S6: —
A7: 6 | B7: 🔄 En cours | C7: 🔥 Immédiatement | D7: 🔴 Haute | E7: Achat | F7: 1M-2M MAD | G7: 212661155182 | H7: Ouardi | I7: Hassan | J7: Agent | M7: ✅ | N7: appel 02 24 / yassir appel 02 25 / nowfel - californie madarona - 3 chmabre -*160 metre care | R7: hassanouardi@gmail.com | S7: —
A8: 7 | B8: 🔄 En cours | C8: 🔥 Immédiatement | D8: 🔴 Haute | E8: Location | F8: 5k-10k | G8: 212633648138 | I8: Zora | M8: ✅ | N8: Deja contacter besoin dun plateau au centre budget max 11k | Taille de l‘équipe : 1-3 personnes | Surface appro : 50 - 100 m2 | P8: Casa | Q8: Bureau | R8: contactzohra5@gmail.com | S8: —
A9: 8 | B9: 🔄 En cours | C9: 🔥 Immédiatement | D9: 🔴 Haute | E9: Vente | F9: 4M+ MAD | G9: 212662858016 | H9: Cohen | I9: Victor | M9: ✅ | N9: rdv a 13h | 7k-10k si location | Q9: Villa | R9: cohenvictor@hotmail.fr | S9: —
A10: 9 | B10: 🔄 En cours | C10: 🔥 Immédiatement | D10: 🔴 Haute | E10: Vente | F10: 1M-2M MAD | G10: 212661319660 | H10: El Hassar Aby | I10: Simo | M10: ✅ | N10: Studio En vente dernier prix 1,1 meuble 40m2 .. | 7k-10k si location | Q10: Studio | R10: melhassar@gmail.com | S10: —
A11: 10 | B11: 🔄 En cours | C11: 🔥 Immédiatement | D11: 🔴 Haute | E11: Vente | F11: -1M MAD | G11: 212644813131 | H11: Serghini Anbari Hassani | I11: Asmae | M11: ✅ | N11: 7k-10k si location | Q11: Appart | R11: asmae.serghini.hassani@gmail.com | S11: —
A12: 11 | B12: 🔄 En cours | C12: 🔥 Immédiatement | D12: 🔴 Haute | E12: Vente | F12: 1M-2M MAD | G12: 212664138772 | H12: Mehdi | I12: Nomadsah | M12: ✅ | N12: Appart avendre 3ch roche noir | 7k-10k si location | Q12: Appart | R12: mehdi.swatch@gmail.com | S12: —
A13: 12 | B13: 🔄 En cours | C13: 🔥 Immédiatement | D13: 🔴 Haute | E13: Louer son bien | F13: 7k-10k | G13: 212600002833 | H13: - | I13: Sofia | M13: ✅ | N13: Studio lhermitage en location | P13: Casa | Q13: Studio | R13: sofiatadili3@gmail.com | S13: —
A14: 13 | B14: 🔄 En cours | C14: 🔥 Immédiatement | D14: 🔴 Haute | E14: Louer son bien | F14: 12k | G14: 212661225622 | H14: Bertoune | I14: Mostafa | M14: ✅ | N14: Appartement 3ch meuble ziraoui sans garage | R14: mostafabertoune@hotmail.fr | S14: —
A15: 14 | B15: 🔄 En cours | C15: 🔥 Immédiatement | D15: 🔴 Haute | E15: Louer son bien | F15: 10k-20k | G15: 212665215221 | H15: Debbagh | I15: Amine | M15: ✅ | N15: open space / surface grande / visite demain 16h | Surface appro : 50 - 100 m2 | P15: Casa | Q15: Plateau open space | R15: a.debbagh.b@gmail.com | S15: —
A16: 15 | B16: 🔄 En cours | C16: 🔥 Immédiatement | D16: 🔴 Haute | E16: Louer son bien | F16: 10k-20k | G16: 212661172418 | I16: Hamid | M16: ✅ | N16: Studio meublé marina | P16: Casa | Q16: Appart | R16: elotmani@lmsorh.com | S16: —
A17: 16 | B17: 🔄 En cours | C17: 🔥 Immédiatement | D17: 🔴 Haute | E17: Louer son bien | F17: 7k-10k | G17: 212674346857 | H17: Robe | I17: Sexy chic | M17: ✅ | N17: Appartement 2chambre en location | P17: Casa | Q17: Appart | R17: sabrinamoghtit@outlook,com | S17: —
A18: 17 | B18: 🔄 En cours | C18: 🔥 Immédiatement | D18: 🔴 Haute | E18: Louer son bien | F18: 7k-10k | G18: 212669953464 | H18: Slilou | I18: Imane | M18: ✅ | N18: Bureau a louer cheikh khalida 8000dh | Q18: Bureau / local commercial | R18: islilou@gmail.com | S18: —
A19: 18 | B19: 🔄 En cours | C19: 📅 Dans 1 mois | D19: 🔴 Haute | E19: Achat | F19: 4M+ MAD | G19: 212661105676 | H19: EL Bidaoui | J19: Karim Zniber | M19: ✅ | N19: Il a un budget: 12 million / Sur ville verte / villa jumelée (600m2-800m2) | O19: Cash | P19: Casablanca | Q19: villa CGI | R19: cuistoquip@gmail.com
A20: 19 | B20: 🔄 En cours | C20: 🔥 Immédiatement | D20: 🟡 Moyenne | E20: Location | G20: 212661182085 | H20: Amine Bououlja | M20: ✅ | N20: Appelez mais il na pas repondu, jai envoye whatsapp | 1 personne | P20: Philadelphia | Q20: studio CFC | R20: bououlja19@hotmail.fr
A21: 20 | B21: 🔄 En cours | C21: 🔥 Immédiatement | D21: 🟡 Moyenne | E21: Location | F21: 5k-10k | G21: 212661431451 | H21: Anas Alami | J21: Karim Zniber | M21: ✅ | N21: Appelez, il a repondu, il veut un investissement locatif CFC et les alentours de 900,000 a 1,100,000 | Repond pas | 1 personne | 7k-10k si location | P21: Casablanca | Q21: studio CFC | R21: Lalamianas@yahoo.fr
A22: 21 | B22: 🔄 En cours | C22: 📅 Dans 1 mois | D22: 🟡 Moyenne | E22: Location | F22: 5k-10k | G22: 212661254575 | H22: Abderrahim Benabdelkrim | J22: Karim Zniber | M22: ✅ | N22: Il recherche pour sa fille, location pour dans 2 mois, budget max 7000MAD meuble, californie, il na pas grande idee de casa car il nest pas dici, a faire un suivi conseil | Couple | P22: meknes | Q22: studio ferme brettone | R22: benabdelkrimabderrahim@gmail.com
A23: 22 | B23: 🔄 En cours | C23: 📅 Dans 1 mois | D23: 🟡 Moyenne | E23: Achat | F23: 2M-4M MAD | G23: 212664926869 | H23: Bennani | I23: Mohamed | J23: Karim Zniber | M23: ✅ | N23: Achat appartement 2,7mdh sur racine, les hopitaux, palmier | P23: Casa | R23: bennani.mohamed92@gmail.com | S23: —
A24: 23 | B24: 🔄 En cours | C24: 📅 Dans 1 mois | D24: 🟡 Moyenne | E24: Achat | F24: 10k-20k | G24: 212658617908 | H24: Ouajid | I24: Salah-eddine | J24: Karim Zniber | M24: ✅ | N24: centre n.owfel appel : recherche immediate platea 75-90m backo /qods /*caliofornie francxe ville abdelmoumen ghandi aqin sbai casa mohjamedia | Taille de l‘équipe : 3-10 personnes | P24: Casa | Q24: Bureau | R24: salahe-1999@hotmail.com | S24: —
A25: 24 | B25: 🔄 En cours | C25: 📅 Dans 1 mois | D25: 🟡 Moyenne | E25: Location | F25: 7k-10k | G25: 212661298829 | H25: Benmassaoud | I25: Samira | R25: samira6107@gmail.com | S25: —
A26: 25 | B26: 🔄 En cours | C26: 📅 Dans 1 mois | D26: 🟡 Moyenne | E26: Location | F26: 10k-20k | G26: 212661430583 | H26: Bendahmane | I26: Hicham | J26: Basma | M26: ✅ | N26: nowfel 25 02 sympatique gas periode transitoire pour le 1er mai habite dans un 160 / orefere ferme bretone cil ain diab 13.03 - Basma no answer | R26: hbendahmane@hotmail.com | S26: —
A27: 26 | B27: ❌ Perdu | C27: 📅 Dans 1 mois | D27: 🟡 Moyenne | E27: Location | F27: 10k-20k | G27: 212661368639 | H27: Dieguez | I27: Angel | M27: ✅ | N27: Villa en location vide, 3ch 3sdb, aindiab- 1 mcdo darbouaza idealm piscine et jardin 25 max | P27: Casa | R27: angel.dieguez@kws.com | S27: —
A28: 27 | B28: 🔄 En cours | C28: 📅 Dans 1 mois | D28: 🟡 Moyenne | E28: Vente | F28: 2M-4M MAD | G28: 212661322610 | H28: Essarhir | I28: Karim | M28: ✅ | N28: 10k-20k si location | Q28: Appart | R28: k.essarhir@hotmail.com | S28: —
A29: 28 | B29: 🔄 En cours | C29: 📅 Dans 1 mois | D29: 🟡 Moyenne | E29: Investissement | F29: -1M MAD (achat) | G29: 212664941993 | H29: Nassiri | I29: Manal | M29: ✅ | N29: Achat studio marrakech(semlalia, gueliz)/casa last option | 7k-10k si location | R29: nassirimanal@gmail.com | S29: —
A30: 29 | B30: 🔄 En cours | C30: 📅 2-3 mois | D30: 🟢 Faible | E30: Location | G30: 212621161018 | H30: Houda Nesbane | M30: ✅ | N30: Famille | P30: Casablanca | Q30: appart hjajma | R30: inefc.houda@gmail.com
A31: 30 | B31: 🔄 En cours | C31: 📅 2-3 mois | D31: 🟢 Faible | E31: Achat | F31: 1M-2M MAD | G31: 212663527171 | H31: Benhayoun | I31: Fawzi | M31: ✅ | N31: Une proposition d'appartement, il demande dautre proposition | R31: parfumdange7@gmail.com | S31: —
A32: 31 | B32: 🔄 En cours | C32: 📅 2-3 mois | D32: 🟢 Faible | E32: Louer son bien | F32: 7k-10k | G32: 212621477755 | H32: Chmite | I32: Mohammed | M32: ✅ | N32: Dici juin | Q32: Appart | R32: mohammedchmitee@gmail.com | S32: —
A33: 32 | B33: 🔄 En cours | C33: 📅 2-3 mois | D33: 🟢 Faible | E33: Louer son bien | F33: 7k-10k | G33: 212661643464 | H33: Azzal El Bouaffi | I33: Khadija | M33: ✅ | N33: Sur Mansouria/mohamed | PAS INTERESSANT | Q33: Appart | R33: bouaffikhadija@gmail.com | S33: —
A34: 33 | B34: ❌ Perdu | C34: 🕐 +6 mois | D34: 🟢 Faible | E34: Location | F34: 10k-20k | G34: 212660745530 | H34: Fatmi Dieguez | I34: Mouna | M34: ✅ | N34: Location de villa entre aindiab extension et premier macdo darbouaza budget max 20k | R34: direction@caddyvoyages.ma | S34: —
A35: 34 | B35: 🔄 En cours | C35: 🔥 Immédiatement | D35: 🟢 Faible | E35: Achat | G35: 212661495155 | H35: Krafess | I35: Ismail | J35: Oumaima | M35: ✅ | N35: DM insta (intéressé par le studio de sefrioui) | P35: Casa | Q35: Studio Sefrioui | S35: —
A36: 35 | B36: ❌ Perdu | C36: 🔥 Immédiatement | D36: 🔴 Haute | E36: Location | F36: 5k-10k | G36: 212661250620 | I36: Walid | M36: ✅ | N36: Domiciliation(erreur) | Taille de l‘équipe : 1-3 personnes | Q36: Bureau pour siège social | R36: walid@icloud.ma | S36: —
A37: 36 | B37: ❌ Perdu | C37: 🔥 Immédiatement | D37: 🔴 Haute | E37: Location | G37: 212661414132 | H37: Zemmouri | I37: Abdessamad | J37: Basma | M37: ✅ | N37: Couple | Deja pris ailleurs | P37: Casa | Q37: Studio Marina Casa | R37: abzemmouri@yahoo.fr | S37: SL-001
A38: 37 | B38: 📋 À traiter | C38: 🔥 Immédiatement | D38: 🔴 Haute | E38: Achat | G38: 212622737793 | H38: Najiba Bouftila | J38: Karim Zniber | M38: ✅ | N38: Elle vient de se casser le bras | O38: Cash | P38: Casablanca | Q38: studio 2 mars | R38: najibabouftila@yahoo.fr
A39: 38 | B39: 🔄 En cours | C39: 🔥 Immédiatement | D39: 🔴 Haute | E39: Achat | G39: 212679003299 | H39: Mohamed | J39: Agent | M39: 📝 | O39: Cash | P39: Casablanca | Q39: Triplex ain diab | R39: hilmimohamed91@gmail.com
A40: 39 | B40: 🔄 En cours | C40: 🔥 Immédiatement | D40: 🔴 Haute | E40: Achat | G40: 212661169383 | H40: Janati | I40: Sana | J40: Karim Zniber | M40: ✅ | N40: Recherche 10-12M, Anfa Sup, Immediatiement, Ain Diab aussi, | O40: Cash | P40: Casablanca | Q40: Villa ain diab | R40: drjanati@hotmail.com
...

Sheet 📌 Guide
A1: 📌 GUIDE RAPIDE — WeHome Leads
A3: FILTRER LES URGENTS
A4: Urgence = 🔥 | B4: Leads qui veulent acheter/louer immédiatement
A5: Catégorie | B5: Achat / Location / Vente...
A6: Agent = vide | B6: Leads pas encore pris par quelqu'un
A7: 📝 = ✅ | B7: Leads avec des infos — lire avant d'appeler
A8: Statut = 🔄 | B8: Mes leads en cours
A10: PRENDRE UN LEAD
A11: 1. Agent | B11: Tape : Karim Zniber / Oumaima / Basma
A12: 2. Statut | B12: Change → 🔄 En cours
A13: 3. Notes | B13: Budget, quartier, remarques
A14: 4. Dernière relance | B14: Date après chaque appel/message
A15: 5. Prochain RDV | B15: Si RDV fixé
A17: URGENCE
A18: 🔥 Immédiatement | B18: Maintenant
A19: 📅 Dans 1 mois | B19: Court terme
A20: 📅 2-3 mois | B20: Moyen terme
A21: 📅 3-6 mois | B21: À relancer
A22: 🕐 +6 mois | B22: Pas urgent
A24: STATUTS
A25: 📋 À traiter | B25: Pas contacté
A26: 🔄 En cours | B26: Deal actif
A27: ✅ Gagné | B27: Signé !
A28: ❌ Perdu | B28: Ne donnera pas suite

Sheet 🏠 Biens
A1: WEHOME / WEOFFICE — PORTEFEUILLE BIENS | 46 biens | ID Bien = référence à copier dans les leads
A2: Pour lier un lead à un bien : copier l'ID Bien (ex: VV-001) dans la colonne 'ID Bien' du lead | Cliquer sur 🔗 pour ouvrir les photos Canva
A3: # | B3: ID Bien | C3: Type | D3: Transaction | E3: Localisation | F3: Prix | G3: Surface | H3: Meublé | I3: Chambres | J3: Salons | K3: SDB | L3: Etage | M3: Facilité vente | N3: Statut | O3: Agent responsable | P3: 📸 Photos pro | Q3: 📷 Anciennes photos | R3: Descriptif | S3: Notes | T3: Propriétaire
A4: 1 | B4: VV-001 | C4: Villa | D4: Vente | E4: CIL | F4: 16 500 000 dh | G4: 649 m² | H4: Non Meublé | I4: 4 | J4: 3 | K4: 3 | L4: 3 niveaux | M4: MOYENNE | N4: En cours | P4: 🔗 Voir photos | Q4: https://www.canva.com/design/DAG-aBBr96U/4y-qyycgVXHyulUBGhBjEw/view?utm_content=DAG-aBBr96U&utm_campaign=designshare&utm_medium=link2&utm_source=uniquelinks&utlId=h817bab6f20 | R4: CIL Villa de 649m2 A vendre Orientation: Sud/ouest 3 Niveau -RDC Triple salons, Sejour, salle de bain -L'ETAGE 4 chambres à coucher Dont 2 suite 2salle de bain -SOUS SOL Cuisine, avec chambre de service Acces garage Chambre gardien -PISCINE
A5: 2 | B5: VV-002 | C5: Villa | D5: Vente | E5: Florida | F5: 12000dh/m | G5: 1145m2 | H5: Non Meublé | I5: 7 | J5: 3 | K5: 6 | M5: MOYENNE (à lancer) | N5: En cours | P5: 🔗 Voir photos | Q5: 🔗 Voir photos | R5: 3niveau Ss : 2ch avc sdb Hamam beldi Installation technique chauffage central Garage pour 5voiture Rc: 3salon dont 1 beldi 2terrasse, une grande cuisine avec terrasse , toilettes pour inviter L’étage : 1 suite parentale avec dressing et sdb avc jacuzzi baignoire et douche 4 chambre indépendante 2 salle de bain
A6: 3 | B6: VV-003 | C6: Villa | D6: Vente | E6: CGI Bouskoura | F6: 16 500 000 MAD | G6: 1080 m² | H6: Non Meublé | I6: 8 | J6: 3 | K6: 8 | L6: 1 niveau | M6: ELEVEE | N6: En cours | P6: 🔗 Voir photos | Q6: 🔗 Voir photos | R6: 🌿 Villa d’exception – CGI Bouskoura | Front Golf ⛳️ Offrez-vous un cadre de vie unique, au cœur de CGI Bouskoura, avec une vue directe sur le golf, sans aucun vis-à-vis, dans un environnement calme et ultra-privilégié. 🏡 Superficie du terrain : 1 080 m² 🔹 Rez-de-chaussée : • 4 suites élégantes (chambre + salle de bain) • Cuisine fonctionnelle et bien agencée 🔹 À l’étage : • 3 salons lumineux aux volumes généreux • 1 espace salle à manger • 4 suites supplémentaires (chambre + salle de bain) • Cuisine indépendante ✨ Une villa idéale pour grande famille, résidence de prestige ou projet haut standing, alliant espace, intimité et vue imprenable sur le golf. 💰 Prix : 16 500 000 DH
A7: 4 | B7: VV-004 | C7: Villa | D7: Vente | E7: Ain Diab | F7: 15 000 000 dh | G7: 600 m² | H7: Non Meublé | I7: 4 | J7: 3 | K7: 4 | L7: 2 niveaux | M7: ELEVEE | N7: En cours | P7: 🔗 Voir photos | Q7: 🔗 Voir photos | R7: Magnifique villa de luxe à vendre ou louer Superficie terrain: 600m2 Située dans un quartier très calme et sécurisé à Ain Diab, à seulement quelques minutes du Morocco Mal Le bien offre : 4 chambres spacieuses 3 salons lumineux Un espace salle à manger 4 salles de bain Un beau jardin privé avec piscine Finition haut standing • Prix de vente : 15 000 000 Dhs Ou bien location Prix: 80,000dh
A8: 5 | B8: VV-005 | C8: Villa | D8: Vente | E8: Dar Bouazza | F8: 3 750 000 dh | G8: 212 m² | H8: Non Meublé | I8: 4 | J8: 3 | K8: 5 | L8: 1 niveau | M8: MOYENNE (à lancer) | N8: En cours | P8: 🔗 Voir photos | Q8: 🔗 Voir photos | R8: Villa de 218m2 composée comme suit : - sous sol : chambre de personnel, salle de bain, garage, hall - ⁠rez de chausée (porte principale): hall d’entrée, sejour ouvert, coin salle a manger, cuisine équipée, salle de bain invitée, salon marocain, double salon europeen, terrasse avec piscine privative, jardin aménagé - ⁠etage: hall central, suite parentale avec dressing salle de bain et terrasse, suite junior avec salle de bain et baie vitrée, 2 grandes chambres dans une avec balcon, salle de bains - ⁠terrasse : accessible et privative Prix : 3.750.000 dhs
A9: 6 | B9: VV-006 | C9: Villa | D9: Vente | E9: Oued Merzegu | F9: 9 Mdh | G9: • Surface terrain : 608 m² • Surface habitable : 540m² | H9: Non Meublé | I9: 6 | J9: 3 | K9: 5 | L9: 3 niveaux | M9: MOYENNE (à lancer) | N9: En cours | P9: 🔗 Voir photos | Q9: 🔗 Voir photos | R9: Très belle villa d’exception Angle à oued merzegu Les Jardins de l’Océan vous propose à la vente une villa indépendante à 3 façades, idéalement située dans le quartier prisé Les Jardins de l’Océan, à deux pas de la mer, des commerces et des espaces verts de qualité. Caractéristiques principales • Surface terrain : 608 m² • Surface habitable : 540m² sur 3 niveaux • Âge du bien : 2 ans • Orientation : Sud‑Est Distribution des pièces • 4 suites parentales (toutes avec dressing et salle de bains privative) • Triple salon ouvert sur terrasses ensoleillées • Suite parentale avec dressing, salle de bain et double terrasse • Chambre de personnel indépendante Équipements & prestations haut de gamme - chauffe eau Chauffe solaire - Clim centrale • Piscine à débordement • Chauffage central & climatisation réversible • Isolation thermique et phonique • Double vitrage • Sanitaires « intelligents » • Cheminée design • Cuisine entièrement équipée • Grand jardin paysager • Garage spacieux + nombreux rangements
A10: 7 | B10: VV-007 | C10: Villa | D10: Vente | E10: Dar Bouazza | F10: 5 400 000 dh 5.2 MD | G10: 490 m² | H10: Non Meublé | I10: 5 | J10: 2 | K10: 3 | L10: 3 niveaux | M10: MOYENNE (à lancer) | N10: En cours | P10: 🔗 Voir photos | Q10: 🔗 Voir photos | R10: Une belle Villa Jumeler moderne En vente Superficie: 490m2 sur 3 niveaux - ⁠RC Double salon Séjour Salle de bain Cuisine Pergola Donne sur piscine Pisigne et jardin - l’étage une suite parentale Et une suite junior 2 chambres Avec leur salle de bain - ⁠- ⁠Cave Chambre Dressing Chambre de personnel Un debarat Garage Terrasse vue mer Prix: 5,400,000dh | T10: us
A11: 8 | B11: VV-008 | C11: Ferme à villa | D11: Vente | E11: Bir Jedid | F11: 4 400 000 dh | G11: 1 Hectare | H11: Non Meublé | M11: MOYENNE (à lancer) | N11: En cours | P11: 🔗 Voir photos | Q11: 🔗 Voir photos | R11: Ferme 1 Hectare Villa de 500m2 avec piscine, et puit Prix: 4,400,000dh | T11: us
A12: 9 | B12: VL-001 | C12: Villa | D12: Location | E12: Californie | F12: 60 000 MAD/mois | G12: 1150 m² | H12: Non Meublé | I12: 3 | J12: 3 | K12: 3 | L12: 2 niveaux | M12: ELEVEE | N12: En cours | P12: 🔗 Voir photos | R12: Californie - Location d’une magnifique villa de 550 m² habitables et 600 m² de terrain sur 4 niveaux - 3 chambres - 3 salles de bains - Piscine intégrée au salon - Exposition Sud-Ouest Produit exceptionnel – Rare sur le marché Au rez de chaussée : - Réception avec plusieurs volumes en baie vitrée - La piscine qui passe sous une partie vitrée du sol de la réception - Une Salle d’eau invités double vasque - Une Cuisine moderne 100% équipée avec îlot central A l’étage : - La suite parentale composée d’une grande chambre à coucher avec terrasse, d’une salle de bain avec baignoire et douche ainsi qu’un dressing - Deux junior suites composée chacune d’une chambre à coucher avec balcon, placards et salle de bain. Au sous-sol : - Grande chambre à coucher en cour anglaise avec salle de bain - La chambre du personnel avec salle d’eau - Hammam Beldi - Garage couvert - La villa bénéficie d’un Chauffage central et d’une climatisation gainée réversible dans toutes les pièces - Parquet massif dans les chambres - Système de vidéo surveillance - Finitions de très haut standing - Proximité de l’école américaine (C.A.S) Prix: 60 000dh/mois 📍Casablanca, Californie
A13: 10 | B13: PL-001 | C13: Penthouse | D13: Location | E13: Ferme Bretonne | F13: 19 000 dh | G13: 125 m² | H13: Meublé | I13: 2 | J13: 1 | K13: 2 | L13: 4 | M13: ELEVEE | N13: En cours | P13: 🔗 Voir photos | Q13: 🔗 Voir photos | R13: 4eme étage Grand salon Cuisine américaine ouverte 2chambre à coucher dont une suite parentale 2 salle de bain | S13: Location
A14: 11 | B14: PL-002 | C14: Penthouse | D14: Location | E14: Ain Diab | F14: 100 000dh/mois | G14: 450 m² | H14: Meublé | I14: 4 | J14: 2 | K14: 5 | L14: 12 | M14: ELEVEE | N14: En cours | P14: 🔗 Voir photos | Q14: 🔗 Voir photos | R14: Penthouse à louer meublé à Ain Diab * grande cuisine avec balcon * ⁠2 salon spacieux * ⁠ une suite parentale * ⁠ salle d’eau pour les invités * ⁠ grand terrasse, double façade À l’étage : * séjour * ⁠ salle de bain * ⁠3 suites avec dressing et salle de bain Pour la location longue durée 100.000 Dhs | S14: Location
A15: 12 | B15: AV-001 | C15: Appartement | D15: Vente | E15: Route d‘Azemmour | F15: 3 750 000,00 DH | G15: 188 m2 | H15: Non Meublé | I15: 3 | J15: 2 | K15: 3 | L15: 1 | M15: ELEVEE | N15: En cours | P15: 🔗 Voir photos | Q15: 🔗 Voir photos | R15: 🏘️Avendre Appartement de Luxe en Front de Mer sur la route d'Azemmour Nous vous proposons un magnifique appartement de standing situé en front de mer, offrant une vue imprenable sur l'océan. ✅Caractéristiques 188 m2 de Superficie généreuse avec ✅3chambres, dont 1 chambre parentale avec dressing ✅2 salons spacieux pour recevoir vos invités Balcon avec vue panoramique sur la mer pour profiter des moments de détente ✅3 salles de bains pour un confort optimal ✅Cuisine équipée pour préparer vos repas favoris Petite chambre avec salle d'eau pour femme de ménage 🚕2 places de parking au garage pour votre commodité 🗃️box au garage 💰prix 3 750 000,00 DH 📍Localisation Situé en front de mer, cet appartement offre une vue unique sur l'océan et profite d'une localisation privilégié à cinq minutes de Morocco Mall
A16: 13 | B16: AV-002 | C16: Appartement | D16: Vente | E16: Roches noires | F16: 1 190 000 dh | G16: 129 m2 | H16: Non Meublé | I16: 2 | J16: 2 | K16: 3 | M16: BOF | N16: En cours | P16: 🔗 Voir photos | Q16: 🔗 Voir photos | R16: appartement de 129 m2 a vendre, quartier Roches Noires Casablanca, bien ensoleillé, composé de : Cuisine avec balcon, Double salons + hall; Séjour; Une suite parentale avec salle de bain, dressing, et balcon; Chambre d’enfant; Salle de bain avec douche; Salle d eau pour invité; Place au garage 2 ascenseurs. Immeuble bien entretenu, bon voisinage et sécurisé.
A17: 14 | B17: AV-003 | C17: Appartement | D17: Vente | E17: Ain Sbaa | F17: 840 000 dh | G17: 83 m2 | H17: Non Meublé | I17: 2 | J17: 1 | K17: 2 | L17: 3 | M17: BOF | N17: En cours | P17: 🔗 Voir photos | Q17: 🔗 Voir photos | R17: Appartement 83m2 place garage titre de 14m2 Ainsbaa alles de jardin 3eme etage avec ascenseur 2chambre salon w2 salle de bain 2balcon Residence fermer securiser 840,000dh | T17: us
A18: 15 | B18: AV-004 | C18: Appartement | D18: Vente | E18: 46083 | H18: Non Meublé | N18: En cours | P18: 🔗 Voir photos | Q18: 🔗 Voir photos
A19: 16 | B19: AV-005 | C19: Appartement Yassir ext | D19: Vente | E19: CFC | F19: 3.8MD | G19: 153 m2 | I19: 2 | J19: 1 | K19: 2 | L19: 12e | N19: En cours | R19: Appartement d’exception à vendre – CFC Situé au 12ᵉ étage d’une résidence neuve fermée et sécurisée au cœur du CFC, ce superbe appartement de 153 m² offre des prestations haut de gamme, une luminosité remarquable et une vue entièrement dégagée sans vis-à-vis. Il bénéficie également de deux magnifiques terrasses, idéales pour profiter d’un cadre de vie rare et privilégié. Pensé pour offrir confort et élégance, l’appartement se compose de : • Un salon spacieux et lumineux ouvrant sur une grande terrasse • Deux chambres, dont une belle suite parentale • Une cuisine moderne aménagée avec buanderie • Deux salles de bain aux finitions soignées • Deux terrasses offrant de beaux espaces extérieurs • Une place de garage titrée La résidence neuve propose des prestations de standing avec salle de sport, sécurité et environnement calme. 📍 Adresse privilégiée au CFC, à proximité immédiate des bureaux, restaurants, commerces et espaces verts.
A20: 17 | B20: AL-001 | C20: Appartement | D20: Location | E20: Marina Casa | F20: 45 000 dh | G20: 220 m² | H20: Meublé | I20: 3 | J20: 2 | K20: 3 | L20: 6 | M20: ELEVEE | N20: En cours | P20: 🔗 Voir photos | Q20: 🔗 Voir photos | R20: EXCLUSIVITÉ – MARINA CASABLANCA Appartement ultra luxueux de 220 m² au cœur de la Marina Sans vis à vis. Double salon spacieux & lumineux 3 chambres, dont une suite parentale Cuisine haut de gamme avec îlot central Chambre de personnel Prestations premium & finitions de standing 2place de Parking & sécurité 24/7 Un bien d’exception pour un art de vivre unique face à l’océan et mosquée Hassan 2 | S20: Location
A21: 18 | B21: AL-002 | C21: Appartement | D21: Location | E21: CFC | F21: 30 000 dh | G21: 168 m² | H21: Meublé | I21: 3 | J21: 1 | K21: 2 | L21: 14 | M21: ELEVEE | N21: En cours | P21: 🔗 Voir photos | R21: Appartement à CFC 14eme étage jamais habité 3 chambres dont une suite parentale avec dressing et salle de bain 2 salles de bain Grande terrasse Résidence avec piscine au rooftop salle de sport et salle de jeux et salle de réunion 30.000 Dhs dernier prix Inclus frais de concierge | S21: Location
A22: 19 | B22: AL-003 | C22: Appartement | D22: Location | E22: Marina Casa | F22: 18000 | G22: 200 m² | H22: Non Meublé | I22: 2 | J22: 1 | K22: 3 | L22: 2 | M22: ELEVEE | N22: En cours | P22: Canva | Q22: 🔗 Voir photos | R22: Cuisine équipée Place garage | S22: Location
A23: 20 | B23: AL-004 | C23: Rez de jardin | D23: Location | E23: Dar Bouazza | F23: 13 500 dh | G23: 140 m² | H23: Meublé | I23: 3 | J23: 2 | K23: 3 | L23: RDJ | M23: ELEVEE | N23: En cours | P23: 🔗 Voir photos | R23: Location Dar Bouazza: Rez-de-jardin d’exception – Volumes loft & grande terrasse Dans une résidence sécurisée, calme et familiale avec 2 piscines, superbe rez-de-jardin de 140 m², orienté Sud-Ouest, offrant des volumes rares et une luminosité exceptionnelle. A 3 minutes de la mer et proches écoles. Prestations : Surface habitable : 140 m² Terrasse de 70 m² avec barbecue construit Hauteur sous plafond 3,50 m – esprit loft Double salon avec cheminée fonctionnelle 3 chambres, dont suite parentale 2 salles de douche 1 salle de bain invités Orientation Sud-Ouest Rez-de-jardin Résidence sécurisée 2 piscines Environnement calme et familial, commerces de proximité: épicerie, pressing, pharmacie. Idéal résidence principale
A24: 21 | B24: AL-005 | C24: Appartement | D24: Location | E24: Bourgogne hjajma | F24: 9500 dh | G24: 125 m2 | H24: Meublé | I24: 2 | J24: 1 | K24: 2 | L24: RDC | M24: ELEVEE | N24: En cours | P24: 🔗 Voir photos | R24: 2 chambres 1 salon 2 salle de bains 1 cuisine et terrasse au rdv. Immeuble avec centre commercial marjane. Sécurité 24/24 à bourgogne hjajma | S24: Location
A25: 22 | B25: AL-006 | C25: Appartement | D25: Location | E25: Racine extension | F25: 9000 dh | G25: 115 m² | H25: Non Meublé | I25: 2 | J25: 1 | K25: 1 | L25: RDC | M25: ELEVEE | N25: En cours | P25: 🔗 Voir photos | R25: Racine extension Racine extension Appartement vide à la location de 115m2 En Rez de chaussée Grand salon Cuisine 2chambres Une salle de bain Une grande terrasse Prix: 9000dh | S25: Location
A26: 23 | B26: AL-007 | C26: Appartement | D26: Location | E26: Abdelmoumen-Oasis | F26: 8000 dh | G26: 45 m² | H26: Meublé | I26: 1 | J26: 1 | K26: 1 | L26: 1er | M26: ELEVEE | N26: En cours | P26: 🔗 Voir photos | R26: Abdelmoumen-oasis Découvrez ce joli appartement de 45 m² situé au 1er étage d’une résidence agréable au cœur de Casablanca. Neuf jamais habite Il se compose de : • Un salon lumineux • 1 chambre confortable • Cuisine américaine équipée • Salle de bain • Place de parking Prix: 8000dh/mois Caution: 2mois Frais dagence: 1 mois de loyer | S26: Location
A27: 24 | B27: DV-001 | C27: Duplex | D27: Vente | E27: Racine - Les Iris | F27: 6 700 000 dh | G27: 327 m² | H27: Non Meublé | I27: 4 | J27: 3 | K27: 3 | L27: 2 et 3e étage | M27: MOYENNE (à lancer) | N27: En cours | Q27: 🔗 Voir photos | R27: Magnifique Duplex Rénové à Racine – Les Iris Découvrez ce superbe duplex entièrement rénové il y a 2 ans, idéalement situé au 2ᵉ et 3ᵉ étage d’une résidence calme et bien entretenue au cœur du quartier Racine (Les Iris). Ce bien d’exception allie l’élégance, la luminosité et le confort moderne, offrant des volumes généreux et une distribution harmonieuse : Composition : • Triple salon spacieux avec de grandes baies vitrées • 4 chambres dont une suite parentale avec salle de bain attenante • 3 salles de bain modernes avec finitions haut de gamme • Cuisine indépendante équipée • Balcons offrant une belle luminosité • Matériaux et finitions de qualité (marbre, parquet, climatisation, menuiserie haut de gamme) Emplacement privilégié : Situé dans un secteur recherché de Racine, proche des commerces, écoles, restaurants et axes principaux.
A28: 25 | B28: DV-002 | C28: Triplex | D28: Vente | E28: Ain Diab | F28: 8 000 000 MAD | G28: 368 m² | H28: Non Meublé | I28: 4 | J28: 3 | K28: 5 | L28: Dernier étage | M28: ELEVEE | N28: En cours | P28: 🔗 Voir photos | Q28: 🔗 Voir photos | R28: 8.000.000 DHS 📍 AIN DIAB - - VENTE D'UN MAGNIFIQUE TRIPLEX DE 368 M² - VUE MER - DERNIER ÉTAGE AVEC CHEMINÉE - 3 CH. ROOF TOP AMÉNAGÉ- JACUZZI 8.000.000 DHS A proximité immédiate de toutes les commodités, dans une résidence de prestige, vente d'un exceptionnel Triplex de 368m² avec terasse et roof top vue mer . Premier niveau 117 m2 : - Une suite parentale avec dressing et salle de bain - 2 chambres avec placard et salle de bain - parquet massif 2 eme niveau 119 m2 : •⁠ ⁠entrée •⁠ ⁠triple réception - ⁠terasse vue mer - ⁠cheminée •⁠ ⁠superbe cuisine avec îlot centrale •⁠ ⁠sanitaire de réception 3 eme niveau 100 m2 : - Roof top couvert aménagé avec parquet massif - Roof top extérieur vue mer - Jacuzzi - chambre du personnel avec salle de bain •⁠ ⁠2 place de parking + Box titrée de 14m2 •⁠ ⁠sécurité 24/24 PRIX DE VENTE: 8.000.000 DHS Honoraires: 2,5% plus TVA (20%) | S28: A ne pas diffuser ( tout modifier)
A29: 26 | B29: SV-001 | C29: Studio | D29: Vente | E29: ZIRAOUI | F29: 1,100,000dh | G29: 40m2 | H29: Meublé | I29: 1 | J29: 1 | K29: 1 | L29: 3 | M29: BOF | N29: En cours | Q29: 🔗 Voir photos | R29: 40m2 Bourgone (lyaute) Studio en vente meublé Place garage Prix: 1,100,000dh Simo Elhassar Abi Studio Lyautee
A30: 27 | B30: SV-002 | C30: Studio | D30: Vente | E30: 46083 | F30: 1 200 000 | G30: 54m2 | H30: Non meublé | I30: 1 | J30: 1 | K30: 1 | L30: 4 | N30: En cours | P30: 🔗 Voir photos | R30: 1,200,000 a la vente ca revient a 22,225MAD/m2 il faudrait taille du balcon
A31: 28 | B31: SL-001 | C31: Studio | D31: Location | E31: Marina Casa | F31: 15 500 | G31: 60m2 | H31: Meublé | I31: 1 | J31: 1 | K31: 1 | L31: 10 | M31: ELEVEE | N31: En cours | P31: 🔗 Voir photos | Q31: 🔗 Voir photos | R31: Appartement Marina 10eme etage Studio 60m2 avec terrasse Vue mosque et plage Pour location longue duree Meublé Place garage FRAIS SYNDICAT INCLUS | S31: Location
A32: 29 | B32: SL-002 | C32: Studio | D32: Location | E32: Ferme bretonne | F32: 8300 dh | G32: 50 m² | H32: Meublé | I32: 1 | J32: 1 | K32: 1 | L32: RDC surélevé | M32: ELEVEE | N32: En cours | P32: 🔗 Voir photos | R32: Ferme bretonne Studio de 50m2 en location meublé Cuisine séparée équipé Rez de chaussée surélevée Prix: 8500dh | S32: Location
A33: 30 | B33: SL-003 | C33: Studio | D33: Location | E33: Ferme Bretonne | F33: 7500 MAD | G33: 59 m² | H33: Meublé | I33: 1 | J33: 1 | K33: 1 | L33: RDC surélevé | M33: ELEVEE | N33: En cours | P33: 🔗 Voir photos | R33: Description du bien • Type : Studio meublé • Surface : 59 m² ￼ • Emplacement : Ferme Bretonne (Hay Arraha), Casablanca — dans un quartier calme, sécurisé, proche de la Casablanca Finance City. ￼ • État : Neuf, tout a été récemment rénové / mis à neuf. • Meubles & équipements : * Salon lumineux avec canapé, table basse, TV, décoration soignée ￼ * Chambre avec lit double, placards intégrés, tables de nuit, rideaux occultants ￼ * Cuisine entièrement équipée (réfrigérateur, four, plaques, micro-ondes, ustensiles, vaisselle) ￼ * Salle de bain moderne avec douche, lavabo, WC, rangements ￼ Avantages / Atouts • Quartier résidentiel calme et sécurisé ￼ • Proche des commodités : transports, commerces, restaurants, supermarchés, etc. ￼ • Bonne desserte et proximité des zones d’affaires (Casablanca Finance City) ce qui est pratique pour les déplacements professionnels. ￼ Loyer & Conditions • Loyer : 7500 DH/mois ￼ • Disponible pour location longue durée | S33: Location
A34: 31 | B34: SL-004 | C34: Studio | D34: Location | E34: CFC | F34: 11000 dh | G34: 65 m² | H34: Meublé | I34: 1 | J34: 1 | K34: 1 | L34: 11e | M34: ELEVEE | N34: En cours | P34: 🔗 Voir photos | Q34: 🔗 Voir photos | R34: Studio meublé à louer – CFC Situé dans le prestigieux quartier Casablanca Finance City, ce magnifique studio de 65 m² se trouve au 11ᵉ étage d’une résidence moderne à Casablanca. Il se compose de : * Double salon spacieux et lumineux * Cuisine américaine ouverte * 1 chambre confortable * 1 salle de bain Conditions de location : * Loyer : 11 000 DH / mois * Caution : 2 mois * Frais d’agence : 1 mois de loyer Studio idéal pour un cadre de vie moderne au cœur de CFC. | S34: Location
A35: 32 | B35: SL-005 | C35: Appartement | D35: Location | E35: Abdelmoumen-Oasis | F35: 8000 dh | G35: 45 m² | H35: Meublé | I35: 1 | J35: 1 | K35: 1 | L35: 1er | M35: ELEVEE | N35: En cours | P35: 🔗 Voir photos | R35: Abdelmoumen-oasis Découvrez ce joli appartement de 45 m² situé au 1er étage d’une résidence agréable au cœur de Casablanca. Neuf jamais habite Il se compose de : • Un salon lumineux • 1 chambre confortable • Cuisine américaine équipée • Salle de bain • Place de parking Prix: 8000dh/mois Caution: 2mois Frais dagence: 1 mois de loyer | S35: Location
A36: 33 | B36: BV-001 | C36: Bureau | D36: Vente | E36: cil 3min de cfc | F36: 2,000,000dh | G36: 91 m2 | H36: Non Meublé | M36: ELEVEE | N36: En cours | P36: 🔗 Voir photos | R36: 91 m2 + 18 de parking Juste à côté de CFC | S36: Vente
A37: 34 | B37: BL-001 | C37: Bureau | D37: Location | E37: Bd Anfa | F37: 45 000 DH / mois | G37: 225 m² | H37: Non Meublé | M37: ELEVEE | N37: En cours | P37: 🔗 Voir photos | R37: Bureau moderne haut standing à louer à Boulvard D’anfa – 225 m² Bureau moderne entièrement aménagé par un architecte d’intérieur, offrant des prestations haut de gamme et des matériaux nobles, idéal pour cabinet professionnel ou siège d’entreprise. Superficie : 225 m² Caractéristiques : Aménagement contemporain et harmonieux Bois massif et portes en noyer naturel Menuiserie aluminium double vitrage Sol en vinyle haut standing Habillage mural complet pour une ambiance élégante et cohérente Climatisation centralisée Composition : Espace accueil Salle d’attente Cuisine équipée Balcon Salle de réunion Espace collaborateurs pouvant accueillir jusqu’à 16 personnes 1 bureau de directeur 1 bureau de chef de cabinet 1 bureau pour 2 collaborateurs du chef de cabinet Bureau clé en main, lumineux, fonctionnel et parfaitement pensé pour une activité professionnelle exigeante. Prix de location : 45 000 DH / mois | S37: Location
A38: 35 | B38: BL-002 | C38: Bureau | D38: Location | E38: CFC | F38: 18500 dh | G38: 72 m2 | H38: Non Meublé | L38: 4 | M38: ELEVEE | N38: En cours | P38: 🔗 Voir photos | R38: 72 Mètre carré avec deux places parking | S38: Location
A39: 36 | B39: BL-003 | C39: Bureau | D39: Location | E39: Oasis | F39: 25.000 HT/mois | G39: 131 m² | H39: Non Meublé | I39: - | J39: - | K39: - | L39: 1er étage | M39: ELEVEE | N39: En cours | P39: 🔗 Voir photos | R39: Bureau Oasis - 1er etage, traversant (2 facades : une sur le boulevard principale et une sur la couts) 131m2 dont 12 de cours + 1 place de parking au s-sol 25.000 HT/mois | S39: Location
A40: 37 | B40: BL-004 | C40: Bureau | D40: Location | E40: Cheikh khalifa | F40: 8000dh | G40: 74 m2 | H40: Non Meublé | L40: 1 | M40: ELEVEE | N40: En cours | P40: 🔗 Voir photos | R40: À LOUER – Plateau bureau neuf de 74 m² – Emplacement stratégique proche de l’Hôpital Cheikh Khalifa Nous proposons à la location un bureau neuf et lumineux de 74 m², situé au 1er étage d’un immeuble professionnel récemment livré, idéalement conçu pour accueillir des activités tertiaires. Caractéristiques principales : • Surface : 74 m² bien agencés, offrant de nombreuses possibilités d’aménagement. • Accessibilité : Deux ascenseurs desservant tous les niveaux pour un accès confortable. • Équipement : • Pré-installation pour kitchenette. • Grande toilette indépendante aménagée. • Place de parking privative en sous-sol (avec deux niveaux de stationnement disponibles). • Environnement professionnel : Immeuble à taille humaine composé uniquement de 30 bureaux, occupé par divers professionnels (médecins, avocats, consultants, etc.). • Localisation : • À seulement 5 minutes de l’Hôpital Cheikh Khalifa, • Proche des grands axes et commodités. Avantages : • Immeuble calme et sécurisé. • Ambiance professionnelle propice à la productivité. • Bâtiment aux normes modernes. | S40: Location
...
